Workbook

Sheet Assumptions
A1: Input | B1: Value | C1: Unit | D1: Basis (see Sources)
A2: PEOPLE
A3: Founder / engineer fully loaded cost | B3: 8000 | C3: $ per person-month | D3: Early-stage founder stipend plus tools; replace with real salaries when hiring
A4: Engineers on the product (year 1) | B4: 2 | C4: people | D4: Two of the three founders on engineering, one on customers
A5: Customer-facing founder | B5: 1 | C5: people
A6: Contract traffic engineer (review) | B6: 150 | C6: $ per hour | D6: HNTB 2024 rate schedule: Engineer I/II $115 to $155 per hour
A7: COMPUTE AND HOSTING
A8: Cloud VM, 32 vCPU on demand | B8: 1.55 | C8: $ per hour | D8: Measured: n2-standard-32, us-west1, September 2026 runs
A9: Machine hours per corridor study (calibration + 20-seed battery) | B9: 5 | C9: hours | D9: Measured: I-24 battery 1.5 to 3.4 h; allow 5 h with reruns
A10: Machine hours per controller sweep (add-on) | B10: 4 | C10: hours | D10: Measured: headway-cap sweep 2.8 h; 500-run sweep about 7 h
A11: Hosting per customer workspace | B11: 60 | C11: $ per month | D11: Small always-on VM plus object storage; single-tenant
A12: Shared infrastructure (CI, domains, monitoring) | B12: 150 | C12: $ per month | D12: Estimate
A13: Storage per study kept for a year | B13: 1 | C13: $ per study | D13: About 2 GB per study at object-storage prices
A14: LABOUR PER STUDY
A15: Engineer hours per study, corridor-specific decisions | B15: 8 | C15: hours | D15: Measured on I-24: about one working day; the reusable part is now code
A16: Engineer hours per new data format (loader) | B16: 8 | C16: hours | D16: About a day of engineering (dossier)
A17: Review hours per study (contract engineer) | B17: 4 | C17: hours | D17: Estimate
A18: Sales hours per closed study | B18: 6 | C18: hours | D18: Estimate: two calls and a proposal
A19: PRICES, PATH A (studies and workspace)
A20: Price per corridor study, consultancy | B20: 3500 | C20: $ | D20: Dossier hypothesis: $1,500 to $5,000; mid-point
A21: Price per agency pilot | B21: 50000 | C21: $ | D21: Dossier hypothesis: $25,000 to $75,000
A22: Annual workspace, consultancy | B22: 20000 | C22: $ per year | D22: Dossier hypothesis: $10,000 to $30,000
A23: Annual lab licence | B23: 2500 | C23: $ per year | D23: Free to $5,000
A24: Data onboarding, new format | B24: 3500 | C24: $ | D24: $2,000 to $5,000 per format
A25: Controller sweep add-on | B25: 2500 | C25: $ | D25: Priced on compute plus review
A26: What the study replaces (engineer weeks by hand) | B26: 2 | C26: weeks | D26: Dossier: weeks of expert time per corridor
A27: Hours per week billed | B27: 40 | C27: hours
A28: Consultant billing rate, senior modeler | B28: 200 | C28: $ per hour | D28: HNTB Chief Planner $226 to $250; Engineer II $141 to $155; $200 as a blended senior rate
A29: PRICES AND COSTS, PATH B (live speed advisory)
A30: Corridor length | B30: 10 | C30: miles | D30: A study corridor like the I-24 SMART Corridor section (17 miles) or half of it
A31: Radar detector sites per mile (both directions) | B31: 2 | C31: sites per mile | D31: Half-mile spacing like the SMART Corridor gantries
A32: Radar detector installed cost per site | B32: 11500 | C32: $ per site | D32: ITS Costs Database: $5,000 (existing pole) to $11,500 (new pole) per site
A33: Radar detector O&M per site per year | B33: 800 | C33: $ per year | D33: Estimate: 7 percent of capital
A34: Probe speed data feed, per centreline mile per year | B34: 750 | C34: $ per mile-year | D34: I-95 Corridor Coalition contract about $750 per centreline mile; Michigan $250,000 statewide
A35: Edge compute and comms per corridor per month | B35: 400 | C35: $ per month | D35: One small server or cloud instance plus cellular backhaul
A36: New VSL gantry, all-in | B36: 900000 | C36: $ per gantry | D36: TDOT I-24 SMART Corridor: 67 gantries, reported $45M to $64M
A37: Gantries needed if the corridor has none | B37: 0 | C37: gantries | D37: Set to 0 to sell into corridors that already have signs or use connected-vehicle channels
A38: Annual subscription per corridor, live advisory | B38: 60000 | C38: $ per year | D38: Hypothesis: priced under an agency's probe-data spend plus one engineer-month
A39: Engineering months to a first live corridor | B39: 9 | C39: person-months | D39: Estimator tier (macro CTM plus Kalman) is designed but not built; sensing integration; agency approvals
A40: VOLUMES BY YEAR (base case)
...

Sheet Cost to build
A1: Phase (dossier timeline) | B1: Person-months | C1: Cloud hours | D1: People cost | E1: Cloud cost | F1: Other | G1: Total | H1: Depends on
A2: Validated corridor: radar counts, merge behaviour, battery rerun, second corridor | B2: 2 | C2: 20 | D2: =B2*Assumptions!$B$3 | E2: =C2*Assumptions!$B$8 | F2: 0 | G2: =D2+E2+F2 | H2: Radar counts; PeMS account
A3: Capacity-aware controller and its sweep | B3: 1.5 | C3: 12 | D3: =B3*Assumptions!$B$3 | E3: =C3*Assumptions!$B$8 | F3: 0 | G3: =D3+E3+F3 | H3: Calibrated corridor
A4: Pilot readiness: auth, per-user projects, hosted deployment, versioned release | B4: 1.5 | C4: 5 | D4: =B4*Assumptions!$B$3 | E4: =C4*Assumptions!$B$8 | F4: 1500 | G4: =D4+E4+F4 | H4: Hosting and identity decisions
A5: First agency pilot: their corridor, their data, a submittable report | B5: 2.5 | C5: 10 | D5: =B5*Assumptions!$B$3 | E5: =C5*Assumptions!$B$8 | F5: 2000 | G5: =D5+E5+F5 | H5: A champion at the agency
A6: Product: multi-tenant hosting, billing, onboarding, documentation site | B6: 3 | C6: 10 | D6: =B6*Assumptions!$B$3 | E6: =C6*Assumptions!$B$8 | F6: 3000 | G6: =D6+E6+F6 | H6: Paying users
A7: Path B foundation: state estimator tier (CTM + Kalman), sensor and probe-data ingestion, advisory interface | B7: 9 | C7: 60 | D7: =B7*Assumptions!$B$3 | E7: =C7*Assumptions!$B$8 | F7: 15000 | G7: =D7+E7+F7 | H7: An agency partner with sensors or signs
A8: Path A to product (first five phases) | B8: =SUM(B2:B6) | G8: =SUM(G2:G6)
A9: Path A plus Path B foundation | B9: =SUM(B2:B7) | G9: =SUM(G2:G7)
A11: Reading it: at founder-stipend cost the whole software path is a low six-figure build; the same plan with three market-rate engineers is roughly three to four times that. Cloud is a rounding error: the measured runs cost single-digit dollars each.

Sheet Unit economics A
A1: Item | B1: Per corridor study | C1: Per agency pilot | D1: Per workspace-year | E1: Note
A2: Price | B2: =Assumptions!$B$20 | C2: =Assumptions!$B$21 | D2: =Assumptions!$B$22 | E2: Assumptions
A3: Cloud compute | B3: =Assumptions!$B$9*Assumptions!$B$8 | C3: =3*Assumptions!$B$9*Assumptions!$B$8+Assumptions!$B$10*Assumptions!$B$8 | D3: =12*Assumptions!$B$11+10*Assumptions!$B$9*Assumptions!$B$8 | E3: A pilot is about three studies plus a sweep; a workspace assumes ten studies a year
A4: Storage | B4: =Assumptions!$B$13 | C4: =3*Assumptions!$B$13 | D4: =10*Assumptions!$B$13
A5: Engineer time (founder cost) | B5: =Assumptions!$B$15/160*Assumptions!$B$3 | C5: =(3*Assumptions!$B$15+Assumptions!$B$16+40)/160*Assumptions!$B$3 | D5: =(20)/160*Assumptions!$B$3 | E5: Pilot adds a loader and about a week of on-site and report work; workspace support 20 h a year
A6: Review (contract engineer) | B6: =Assumptions!$B$17*Assumptions!$B$6 | C6: =3*Assumptions!$B$17*Assumptions!$B$6 | D6: =0 | E6: Workspace customers review their own studies
A7: Sales time (founder cost) | B7: =Assumptions!$B$18/160*Assumptions!$B$3 | C7: =40/160*Assumptions!$B$3 | D7: =16/160*Assumptions!$B$3 | E7: A pilot takes about a week of selling across the procurement cycle
A8: Cost of delivery | B8: =SUM(B3:B7) | C8: =SUM(C3:C7) | D8: =SUM(D3:D7)
A9: Gross margin | B9: =(B2-B8)/B2 | C9: =(C2-C8)/C2 | D9: =(D2-D8)/D2
A10: What the customer pays today for the same work | B10: =Assumptions!$B$26*Assumptions!$B$27*Assumptions!$B$28 | E10: Two weeks of a senior modeler at a blended $200 per hour; the study price is a fraction of it, which is the wedge
A11: Customer saving per study | B11: =B10-B2

Sheet Path B live advisory
A1: Item | B1: Per corridor | C1: Note
A2: Corridor length (miles) | B2: =Assumptions!$B$30
A3: Radar sites | B3: =B2*Assumptions!$B$31 | C3: Half-mile spacing, both directions
A4: Sensing capital (radar, installed) | B4: =B3*Assumptions!$B$32 | C4: ITS Costs Database range; existing poles cut it in half
A5: Sensing O&M per year | B5: =B3*Assumptions!$B$33
A6: Probe data feed per year (alternative or complement to radar) | B6: =B2*Assumptions!$B$34 | C6: Buy speeds instead of installing sensors where the agency already licenses probe data
A7: Edge compute and comms per year | B7: =12*Assumptions!$B$35
A8: New gantries (only if the corridor has none) | B8: =Assumptions!$B$37*Assumptions!$B$36 | C8: The SMART Corridor spent about $0.7M to $1M per gantry; the software path avoids this by using existing signs or connected-vehicle channels
A9: Capital, corridor with existing signs | B9: =B4+B8
A10: Operating cost per year | B10: =B5+B7+B6 | C10: Radar O&M plus probe feed plus compute (drop the probe feed if radar alone)
A11: FlowState subscription per year | B11: =Assumptions!$B$38 | C11: Hypothesis
A12: FlowState cost to serve per year (hosting, estimator, one engineer-week a quarter) | B12: =12*Assumptions!$B$11+4*40/160*Assumptions!$B$3
A13: Gross margin on the subscription | B13: =(B11-B12)/B11
A14: Agency's first-year outlay (capital + operating + subscription) | B14: =B9+B10+B11 | C14: Who pays for sensing is the deal structure question
A15: One-time build to reach a first live corridor (FlowState side) | B15: =Assumptions!$B$39*Assumptions!$B$3 | C15: Estimator tier, ingestion, advisory interface, approvals
A17: What Path B is: sensors or probe data feed a live state estimate of the corridor; the calibrated twin turns it into a recommended speed per segment until the wave clears; the advisory reaches drivers through the agency's signs or a connected-vehicle channel run by a partner, never a consumer app of ours (CLAUDE.md section 0.4). It is a subscription, not a study, and its cost is dominated by the agency's sensing, not by us.
A18: What it needs first: the state-estimation tier (designed, not built), a validated corridor twin, and one agency willing to connect its sensors. Price it under the agency's probe-data spend and one engineer-month a year.

Sheet P&L 3 years
A1: Line | B1: Year 1 | C1: Year 2 | D1: Year 3 | E1: Note
A2: REVENUE, PATH A
A3: Corridor studies | B3: =Assumptions!$B$41*Assumptions!$B$20 | C3: =Assumptions!$B$42*Assumptions!$B$20 | D3: =Assumptions!$B$43*Assumptions!$B$20
A4: Agency pilots | B4: =Assumptions!$B$44*Assumptions!$B$21 | C4: =Assumptions!$B$45*Assumptions!$B$21 | D4: =Assumptions!$B$46*Assumptions!$B$21
A5: Workspaces | B5: =Assumptions!$B$47*Assumptions!$B$22 | C5: =Assumptions!$B$48*Assumptions!$B$22 | D5: =Assumptions!$B$49*Assumptions!$B$22
A6: Lab licences | B6: =Assumptions!$B$50*Assumptions!$B$23 | C6: =Assumptions!$B$51*Assumptions!$B$23 | D6: =Assumptions!$B$52*Assumptions!$B$23
A7: REVENUE, PATH B
A8: Live-advisory subscriptions | B8: =Assumptions!$B$53*Assumptions!$B$38 | C8: =Assumptions!$B$54*Assumptions!$B$38 | D8: =Assumptions!$B$55*Assumptions!$B$38
A9: Total revenue | B9: =SUM(B3:B6)+B8 | C9: =SUM(C3:C6)+C8 | D9: =SUM(D3:D6)+D8
A10: COST OF DELIVERY
A11: Studies (cloud, storage, review, engineer time) | B11: =Assumptions!$B$41*'Unit economics A'!$B$8 | C11: =Assumptions!$B$42*'Unit economics A'!$B$8 | D11: =Assumptions!$B$43*'Unit economics A'!$B$8
A12: Pilots | B12: =Assumptions!$B$44*'Unit economics A'!$C$8 | C12: =Assumptions!$B$45*'Unit economics A'!$C$8 | D12: =Assumptions!$B$46*'Unit economics A'!$C$8
A13: Workspaces | B13: =Assumptions!$B$47*'Unit economics A'!$D$8 | C13: =Assumptions!$B$48*'Unit economics A'!$D$8 | D13: =Assumptions!$B$49*'Unit economics A'!$D$8
A14: Live-advisory cost to serve | B14: =Assumptions!$B$53*'Path B live advisory'!$B$12 | C14: =Assumptions!$B$54*'Path B live advisory'!$B$12 | D14: =Assumptions!$B$55*'Path B live advisory'!$B$12
A15: Gross profit | B15: =B9-SUM(B11:B14) | C15: =C9-SUM(C11:C14) | D15: =D9-SUM(D11:D14)
A16: OPERATING COST
A17: People (engineering + customer founder) | B17: =12*(Assumptions!$B$4+Assumptions!$B$5)*Assumptions!$B$3 | C17: =12*(Assumptions!$B$4+Assumptions!$B$5+1)*Assumptions!$B$3 | D17: =12*(Assumptions!$B$4+Assumptions!$B$5+3)*Assumptions!$B$3
A18: Shared infrastructure | B18: =12*Assumptions!$B$12 | C18: =12*Assumptions!$B$12 | D18: =12*Assumptions!$B$12
A19: Build programme cloud (from Cost to build) | B19: ='Cost to build'!E2+'Cost to build'!E3+'Cost to build'!E4 | C19: ='Cost to build'!E5+'Cost to build'!E6+'Cost to build'!E7*0.5 | D19: ='Cost to build'!E7*0.5
A20: Travel, conferences, legal, insurance | B20: 6000 | C20: 15000 | D20: 30000
A21: Operating profit | B21: =B15-SUM(B17:B20) | C21: =C15-SUM(C17:C20) | D21: =D15-SUM(D17:D20)
A22: Cumulative cash need | B22: =MIN(0,B21) | C22: =B22+MIN(0,C21) | D22: =C22+MIN(0,D21)
A24: Base case volumes live on the Assumptions sheet; change them there. Year-one revenue is tens of thousands of dollars, which matches the dossier's own sizing; the model is not a forecast, it is the arithmetic the conversation should test.
A25: Scenario guide: conservative = halve every volume; upside = double year-2 and year-3 studies and add two live corridors in year 3. Both are one edit each on the Assumptions sheet.

Sheet Sources
A1: Anchor | B1: Source
A2: Cloud cost $1.55 per hour, 32 vCPUs; studies 1.5 to 3.4 machine hours; sweeps 2.8 to 7 hours | B2: FlowState repository, scripts/gcp/README.md and docs/I24_SWEEP.md (measured, September 2026)
A3: Consultant rates: Engineer I $115 to $127, Engineer II $141 to $155, Chief Planner $226 to $250 per hour | B3: HNTB Corporation consultant fee schedule (Wisconsin Division of Facilities Development, 2009-10 rate sheet; 2024 schedules on file with California cities such as Chula Vista for Kimley-Horn)
A4: Two weeks of expert calibration per corridor; rejected reports are common | B4: FlowState technical dossier section 7.1; FHWA Traffic Analysis Toolbox Volume III, 2019 update (FHWA-HOP-18-036)
A5: Radar detector site $5,000 (existing pole) to $11,500 (new pole) | B5: USDOT ITS Costs Database, Roadside Detection, Remote Traffic Microwave Sensor on Corridor (itscosts.its.dot.gov / itskrs.its.dot.gov)
A6: Probe data: about $750 per centreline mile (I-95 Corridor Coalition original contract); $250,000 statewide (Michigan); INRIX at about 25 percent of NCDOT's previous $50,000 per mile life-cycle cost | B6: USDOT ITS Knowledge Resources 2014-SC00327; INRIX press releases
A7: I-24 SMART Corridor: 67 gantries at half-mile spacing between mile markers 53 and 70; reported cost $45M to $64M | B7: Tennessee DOT project page; NewsChannel 5 and WKRN reports; Roads and Bridges
A8: 400+ MPOs; 52 state DOTs | B8: AMPO MPO 101 brief; FHWA
A9: Price hypotheses: $1,500 to $5,000 per study; $10,000 to $30,000 workspace; $25,000 to $75,000 pilot; $2,000 to $5,000 per data format | B9: FlowState technical dossier section 8.1 (hypotheses to test in interviews)
A10: Commercial simulator licences are five figures per seat | B10: Vendor pricing is not public (PTV pricing page); dossier estimate from practitioner reports
